2024-08-23 23:48:10,059 - INFO - [31m[1mWARNING: This is a development server. Do not use it in a production deployment. Use a production WSGI server instead.[0m
 * Running on all addresses (0.0.0.0)
 * Running on http://127.0.0.1:5000
 * Running on http://192.168.1.2:5000
2024-08-23 23:48:10,059 - INFO - [33mPress CTRL+C to quit[0m
2024-08-23 23:48:13,489 - INFO - 127.0.0.1 - - [23/Aug/2024 23:48:13] "GET / HTTP/1.1" 200 -
2024-08-23 23:48:13,600 - INFO - 127.0.0.1 - - [23/Aug/2024 23:48:13] "[33mGET /favicon.ico HTTP/1.1[0m" 404 -
2024-08-23 23:48:20,434 - INFO - 127.0.0.1 - - [23/Aug/2024 23:48:20] "GET /predictdata HTTP/1.1" 200 -
2024-08-23 23:48:38,068 - ERROR - Exception on /predictdata [POST]
Traceback (most recent call last):
  File "c:\Users\AnkushAnkush2\Desktop\Machine_Learning_Project\src\components\predict_pipeline.py", line 16, in predict
    model=load_object(file_path=model_path)
          ^^^^^^^^^^^^^^^^^^^^^^^^^^^^^^^^^
TypeError: 'module' object is not callable

During handling of the above exception, another exception occurred:

Traceback (most recent call last):
  File "C:\Users\AnkushAnkush2\AppData\Local\Programs\Python\Python312\Lib\site-packages\flask\app.py", line 1473, in wsgi_app
    response = self.full_dispatch_request()
               ^^^^^^^^^^^^^^^^^^^^^^^^^^^^
  File "C:\Users\AnkushAnkush2\AppData\Local\Programs\Python\Python312\Lib\site-packages\flask\app.py", line 882, in full_dispatch_request
    rv = self.handle_user_exception(e)
         ^^^^^^^^^^^^^^^^^^^^^^^^^^^^^
  File "C:\Users\AnkushAnkush2\AppData\Local\Programs\Python\Python312\Lib\site-packages\flask\app.py", line 880, in full_dispatch_request
    rv = self.dispatch_request()
         ^^^^^^^^^^^^^^^^^^^^^^^
  File "C:\Users\AnkushAnkush2\AppData\Local\Programs\Python\Python312\Lib\site-packages\flask\app.py", line 865, in dispatch_request
    return self.ensure_sync(self.view_functions[rule.endpoint])(**view_args)  # type: ignore[no-any-return]
           ^^^^^^^^^^^^^^^^^^^^^^^^^^^^^^^^^^^^^^^^^^^^^^^^^^^^^^^^^^^^^^^^^
  File "c:\Users\AnkushAnkush2\Desktop\Machine_Learning_Project\src\components\app.py", line 42, in predict_datapoint
    results=predict_pipeline.predict(pred_df)
            ^^^^^^^^^^^^^^^^^^^^^^^^^^^^^^^^^
  File "c:\Users\AnkushAnkush2\Desktop\Machine_Learning_Project\src\components\predict_pipeline.py", line 24, in predict
    raise CustomError(e,sys)
          ^^^^^^^^^^^^^^^^^^
TypeError: 'module' object is not callable
2024-08-23 23:48:38,073 - INFO - 127.0.0.1 - - [23/Aug/2024 23:48:38] "[35m[1mPOST /predictdata HTTP/1.1[0m" 500 -
2024-08-23 23:49:21,011 - INFO - [31m[1mWARNING: This is a development server. Do not use it in a production deployment. Use a production WSGI server instead.[0m
 * Running on all addresses (0.0.0.0)
 * Running on http://127.0.0.1:5000
 * Running on http://192.168.1.2:5000
2024-08-23 23:49:21,011 - INFO - [33mPress CTRL+C to quit[0m
